Error executing job with overrides: []
Traceback (most recent call last):
  File "C:\Users\Admin\AppData\Local\Programs\Python\Python310\lib\site-packages\huggingface_hub\utils\_errors.py", line 304, in hf_raise_for_status
    response.raise_for_status()
  File "C:\Users\Admin\AppData\Local\Programs\Python\Python310\lib\site-packages\requests\models.py", line 1024, in raise_for_status
    raise HTTPError(http_error_msg, response=self)
requests.exceptions.HTTPError: 401 Client Error: Unauthorized for url: https://huggingface.co/nguyenvulebinh/wav2vec2-large-vi-vlsp/resolve/main/config.json

The above exception was the direct cause of the following exception:

Traceback (most recent call last):
  File "C:\Users\Admin\AppData\Local\Programs\Python\Python310\lib\site-packages\transformers\utils\hub.py", line 402, in cached_file
    resolved_file = hf_hub_download(
  File "C:\Users\Admin\AppData\Local\Programs\Python\Python310\lib\site-packages\huggingface_hub\utils\_deprecation.py", line 101, in inner_f
    return f(*args, **kwargs)
  File "C:\Users\Admin\AppData\Local\Programs\Python\Python310\lib\site-packages\huggingface_hub\utils\_validators.py", line 114, in _inner_fn
    return fn(*args, **kwargs)
  File "C:\Users\Admin\AppData\Local\Programs\Python\Python310\lib\site-packages\huggingface_hub\file_download.py", line 1240, in hf_hub_download
    return _hf_hub_download_to_cache_dir(
  File "C:\Users\Admin\AppData\Local\Programs\Python\Python310\lib\site-packages\huggingface_hub\file_download.py", line 1347, in _hf_hub_download_to_cache_dir
    _raise_on_head_call_error(head_call_error, force_download, local_files_only)
  File "C:\Users\Admin\AppData\Local\Programs\Python\Python310\lib\site-packages\huggingface_hub\file_download.py", line 1854, in _raise_on_head_call_error
    raise head_call_error
  File "C:\Users\Admin\AppData\Local\Programs\Python\Python310\lib\site-packages\huggingface_hub\file_download.py", line 1751, in _get_metadata_or_catch_error
    metadata = get_hf_file_metadata(
  File "C:\Users\Admin\AppData\Local\Programs\Python\Python310\lib\site-packages\huggingface_hub\utils\_validators.py", line 114, in _inner_fn
    return fn(*args, **kwargs)
  File "C:\Users\Admin\AppData\Local\Programs\Python\Python310\lib\site-packages\huggingface_hub\file_download.py", line 1673, in get_hf_file_metadata
    r = _request_wrapper(
  File "C:\Users\Admin\AppData\Local\Programs\Python\Python310\lib\site-packages\huggingface_hub\file_download.py", line 376, in _request_wrapper
    response = _request_wrapper(
  File "C:\Users\Admin\AppData\Local\Programs\Python\Python310\lib\site-packages\huggingface_hub\file_download.py", line 400, in _request_wrapper
    hf_raise_for_status(response)
  File "C:\Users\Admin\AppData\Local\Programs\Python\Python310\lib\site-packages\huggingface_hub\utils\_errors.py", line 352, in hf_raise_for_status
    raise RepositoryNotFoundError(message, response) from e
huggingface_hub.utils._errors.RepositoryNotFoundError: 401 Client Error. (Request ID: Root=1-6810c0ec-2a1781b27b218eb0722a3424;c7e10bfc-7e22-4231-83da-5c7a0f1f5260)

Repository Not Found for url: https://huggingface.co/nguyenvulebinh/wav2vec2-large-vi-vlsp/resolve/main/config.json.
Please make sure you specified the correct `repo_id` and `repo_type`.
If you are trying to access a private or gated repo, make sure you are authenticated.
Invalid username or password.

The above exception was the direct cause of the following exception:

Traceback (most recent call last):
  File "D:\Quan\Code\KSCS\AutomaticSpeed\main.py", line 13, in main
    trainer = ASRTrainer(config)
  File "D:\Quan\Code\KSCS\AutomaticSpeed\src\training\trainer.py", line 30, in __init__
    self.model = VietnameseASRModel(config).to(self.device)
  File "D:\Quan\Code\KSCS\AutomaticSpeed\src\models\model.py", line 12, in __init__
    self.model = Wav2Vec2ForCTC.from_pretrained(
  File "C:\Users\Admin\AppData\Local\Programs\Python\Python310\lib\site-packages\transformers\modeling_utils.py", line 3203, in from_pretrained
    resolved_config_file = cached_file(
  File "C:\Users\Admin\AppData\Local\Programs\Python\Python310\lib\site-packages\transformers\utils\hub.py", line 425, in cached_file
    raise EnvironmentError(
OSError: nguyenvulebinh/wav2vec2-large-vi-vlsp is not a local folder and is not a valid model identifier listed on 'https://huggingface.co/models'
If this is a private repository, make sure to pass a token having permission to this repo either by logging in with `huggingface-cli login` or by passing `token=<your_token>`

Set the environment variable HYDRA_FULL_ERROR=1 for a complete stack trace.
